2020-03-07 22:37:04,306 -  nornir.core -     INFO -        run() - Running task 'nornir_group_of_tasks' with args {'list_of_commands': ['uname -a', 'arp -a', 'whoami']} on 2 hosts
2020-03-07 22:38:49,559 -  nornir.core -     INFO -        run() - Running task 'nornir_group_of_tasks' with args {'list_of_commands': ['uname -a', 'arp -a', 'whoami']} on 2 hosts
2020-03-07 22:39:07,819 -  nornir.core -     INFO -        run() - Running task 'nornir_group_of_tasks' with args {'list_of_commands': ['uname -a', 'arp -a', 'whoami']} on 2 hosts
2020-03-07 22:49:44,904 -  nornir.core -     INFO -        run() - Running task 'nornir_group_of_tasks' with args {'list_of_commands': ['uname -a', 'arp -a', 'whoami']} on 2 hosts
2020-03-08 06:01:48,030 -  nornir.core -     INFO -        run() - Running task 'nornir_group_of_tasks' with args {'list_of_commands': ['uname -a', 'arp -a', 'whoami']} on 2 hosts
2020-03-08 06:02:25,991 -  nornir.core -     INFO -        run() - Running task 'nornir_group_of_tasks' with args {'list_of_commands': ['uname -a', 'arp -a', 'whoami']} on 2 hosts
2020-03-08 06:08:23,387 -  nornir.core -     INFO -        run() - Running task 'nornir_group_of_tasks' with args {'list_of_commands': ['uname -a', 'arp -a', 'whoami']} on 2 hosts
2020-03-08 06:09:00,940 -  nornir.core -     INFO -        run() - Running task 'nornir_group_of_tasks' with args {'list_of_commands': ['uname -a', 'arp -a', 'whoami']} on 2 hosts
2020-03-08 06:09:33,304 -  nornir.core -     INFO -        run() - Running task 'nornir_group_of_tasks' with args {'list_of_commands': ['uname -a', 'arp -a', 'whoami']} on 2 hosts
2020-03-08 06:10:35,637 -  nornir.core -     INFO -        run() - Running task 'nornir_group_of_tasks' with args {'list_of_commands': ['uname -a', 'arp -a', 'whoami']} on 2 hosts
2020-03-08 06:10:47,204 -  nornir.core -     INFO -        run() - Running task 'nornir_group_of_tasks' with args {'list_of_commands': ['uname -a', 'arp -a', 'whoami']} on 2 hosts
2020-03-08 06:11:05,248 -  nornir.core -     INFO -        run() - Running task 'nornir_group_of_tasks' with args {'list_of_commands': ['uname -a', 'arp -a', 'whoami']} on 2 hosts
2020-03-08 22:00:54,156 -  nornir.core -     INFO -        run() - Running task 'nornir_group_of_tasks' with args {'list_of_commands': ['uname -a', 'arp -a', 'whoami']} on 2 hosts
2020-03-08 22:01:15,164 - nornir.core.task -    ERROR -      start() - Host 'SERVER2': task 'netmiko_send_command' failed with traceback:
Traceback (most recent call last):
  File "C:\Program Files (x86)\Python38-32\lib\site-packages\netmiko\base_connection.py", line 892, in establish_connection
    self.remote_conn_pre.connect(**ssh_connect_params)
  File "C:\Program Files (x86)\Python38-32\lib\site-packages\paramiko\client.py", line 349, in connect
    retry_on_signal(lambda: sock.connect(addr))
  File "C:\Program Files (x86)\Python38-32\lib\site-packages\paramiko\util.py", line 283, in retry_on_signal
    return function()
  File "C:\Program Files (x86)\Python38-32\lib\site-packages\paramiko\client.py", line 349, in <lambda>
    retry_on_signal(lambda: sock.connect(addr))
TimeoutError: [WinError 10060] Une tentative de connexion a échoué car le parti connecté n’a pas répondu convenablement au-delà d’une certaine durée ou une connexion établie a échoué car l’hôte de connexion n’a pas répondu

During handling of the above exception, another exception occurred:

Traceback (most recent call last):
  File "C:\Program Files (x86)\Python38-32\lib\site-packages\nornir\core\task.py", line 85, in start
    r = self.task(self, **self.params)
  File "C:\Program Files (x86)\Python38-32\lib\site-packages\nornir\plugins\tasks\networking\netmiko_send_command.py", line 26, in netmiko_send_command
    net_connect = task.host.get_connection("netmiko", task.nornir.config)
  File "C:\Program Files (x86)\Python38-32\lib\site-packages\nornir\core\inventory.py", line 294, in get_connection
    self.open_connection(
  File "C:\Program Files (x86)\Python38-32\lib\site-packages\nornir\core\inventory.py", line 345, in open_connection
    self.connections[connection].open(
  File "C:\Program Files (x86)\Python38-32\lib\site-packages\nornir\plugins\connections\netmiko.py", line 58, in open
    self.connection = ConnectHandler(**parameters)
  File "C:\Program Files (x86)\Python38-32\lib\site-packages\netmiko\ssh_dispatcher.py", line 252, in ConnectHandler
    return ConnectionClass(*args, **kwargs)
  File "C:\Program Files (x86)\Python38-32\lib\site-packages\netmiko\base_connection.py", line 318, in __init__
    self._open()
  File "C:\Program Files (x86)\Python38-32\lib\site-packages\netmiko\base_connection.py", line 323, in _open
    self.establish_connection()
  File "C:\Program Files (x86)\Python38-32\lib\site-packages\netmiko\base_connection.py", line 898, in establish_connection
    raise NetmikoTimeoutException(msg)
netmiko.ssh_exception.NetmikoTimeoutException: Connection to device timed-out: linux 192.168.0.105:22

2020-03-09 07:09:27,624 -  nornir.core -     INFO -        run() - Running task 'nornir_group_of_tasks' with args {'list_of_commands': ['uname -a', 'arp -a', 'whoami']} on 2 hosts
2020-03-09 07:21:02,904 -  nornir.core -     INFO -        run() - Running task 'nornir_group_of_tasks' with args {'list_of_commands': ['uname -a', 'arp -a', 'whoami']} on 2 hosts
2020-03-09 07:21:28,288 -  nornir.core -     INFO -        run() - Running task 'nornir_group_of_tasks' with args {'list_of_commands': ['uname -a', 'arp -a', 'whoami']} on 2 hosts
2020-03-09 07:21:49,325 - nornir.core.task -    ERROR -      start() - Host 'SERVER2': task 'netmiko_send_command' failed with traceback:
Traceback (most recent call last):
  File "C:\Program Files (x86)\Python38-32\lib\site-packages\netmiko\base_connection.py", line 892, in establish_connection
    self.remote_conn_pre.connect(**ssh_connect_params)
  File "C:\Program Files (x86)\Python38-32\lib\site-packages\paramiko\client.py", line 349, in connect
    retry_on_signal(lambda: sock.connect(addr))
  File "C:\Program Files (x86)\Python38-32\lib\site-packages\paramiko\util.py", line 283, in retry_on_signal
    return function()
  File "C:\Program Files (x86)\Python38-32\lib\site-packages\paramiko\client.py", line 349, in <lambda>
    retry_on_signal(lambda: sock.connect(addr))
TimeoutError: [WinError 10060] Une tentative de connexion a échoué car le parti connecté n’a pas répondu convenablement au-delà d’une certaine durée ou une connexion établie a échoué car l’hôte de connexion n’a pas répondu

During handling of the above exception, another exception occurred:

Traceback (most recent call last):
  File "C:\Program Files (x86)\Python38-32\lib\site-packages\nornir\core\task.py", line 85, in start
    r = self.task(self, **self.params)
  File "C:\Program Files (x86)\Python38-32\lib\site-packages\nornir\plugins\tasks\networking\netmiko_send_command.py", line 26, in netmiko_send_command
    net_connect = task.host.get_connection("netmiko", task.nornir.config)
  File "C:\Program Files (x86)\Python38-32\lib\site-packages\nornir\core\inventory.py", line 294, in get_connection
    self.open_connection(
  File "C:\Program Files (x86)\Python38-32\lib\site-packages\nornir\core\inventory.py", line 345, in open_connection
    self.connections[connection].open(
  File "C:\Program Files (x86)\Python38-32\lib\site-packages\nornir\plugins\connections\netmiko.py", line 58, in open
    self.connection = ConnectHandler(**parameters)
  File "C:\Program Files (x86)\Python38-32\lib\site-packages\netmiko\ssh_dispatcher.py", line 252, in ConnectHandler
    return ConnectionClass(*args, **kwargs)
  File "C:\Program Files (x86)\Python38-32\lib\site-packages\netmiko\base_connection.py", line 318, in __init__
    self._open()
  File "C:\Program Files (x86)\Python38-32\lib\site-packages\netmiko\base_connection.py", line 323, in _open
    self.establish_connection()
  File "C:\Program Files (x86)\Python38-32\lib\site-packages\netmiko\base_connection.py", line 898, in establish_connection
    raise NetmikoTimeoutException(msg)
netmiko.ssh_exception.NetmikoTimeoutException: Connection to device timed-out: linux 192.168.0.105:22

2020-03-09 13:27:30,977 -  nornir.core -     INFO -        run() - Running task 'nornir_group_of_tasks' with args {'list_of_commands': ['uname -a', 'arp -a', 'whoami']} on 2 hosts
2020-03-09 13:29:01,067 -  nornir.core -     INFO -        run() - Running task 'nornir_group_of_tasks' with args {'list_of_commands': ['uname -a', 'arp -a', 'whoami']} on 2 hosts
2020-03-09 13:30:17,670 -  nornir.core -     INFO -        run() - Running task 'nornir_group_of_tasks' with args {'list_of_commands': ['uname -a', 'arp -a', 'whoami']} on 2 hosts
2020-03-09 13:31:32,570 -  nornir.core -     INFO -        run() - Running task 'nornir_group_of_tasks' with args {'list_of_commands': ['uname -a', 'arp -a', 'whoami']} on 2 hosts
2020-03-09 20:50:07,417 -  nornir.core -     INFO -        run() - Running task 'nornir_group_of_tasks' with args {'list_of_commands': ['uname -a', 'arp -a', 'whoami']} on 2 hosts
2020-03-09 20:50:46,581 -  nornir.core -     INFO -        run() - Running task 'nornir_group_of_tasks' with args {'list_of_commands': ['uname -a', 'arp -a', 'whoami']} on 2 hosts
2020-03-09 20:51:28,217 -  nornir.core -     INFO -        run() - Running task 'nornir_group_of_tasks' with args {'list_of_commands': ['uname -a', 'arp -a', 'whoami']} on 2 hosts
2020-03-09 20:51:47,002 -  nornir.core -     INFO -        run() - Running task 'nornir_group_of_tasks' with args {'list_of_commands': ['uname -a', 'arp -a', 'whoami']} on 2 hosts
2020-03-09 21:02:30,652 -  nornir.core -     INFO -        run() - Running task 'nornir_group_of_tasks' with args {'list_of_commands': ['uname -a', 'arp -a', 'whoami']} on 2 hosts
2020-03-11 07:29:04,519 -  nornir.core -     INFO -        run() - Running task 'nornir_group_of_tasks' with args {'list_of_commands': ['uname -a', 'arp -a', 'whoami']} on 2 hosts
2020-03-11 07:33:51,944 -  nornir.core -     INFO -        run() - Running task 'nornir_group_of_tasks' with args {'list_of_commands': ['uname -a', 'arp -a', 'whoami']} on 2 hosts
2020-03-11 07:34:20,181 -  nornir.core -     INFO -        run() - Running task 'nornir_group_of_tasks' with args {'list_of_commands': ['uname -a', 'arp -a', 'whoami']} on 2 hosts
2020-03-11 21:14:53,645 -  nornir.core -     INFO -        run() - Running task 'nornir_group_of_tasks' with args {'dict_of_devices': {'Switch01': {'hostname': '192.168.0.1', 'port': 22, 'username': 'cisco', 'password': 'cisco', 'platform': 'cisco_ios', 'commands': ['show arp', 'show clock', 'show inventory']}}} on 1 hosts
2020-03-11 21:18:31,986 -  nornir.core -     INFO -        run() - Running task 'nornir_group_of_tasks' with args {'dict_of_devices': {'Switch01': {'hostname': '192.168.0.1', 'port': 22, 'username': 'cisco', 'password': 'cisco', 'platform': 'cisco_ios', 'commands': ['show arp', 'show clock', 'show inventory']}}} on 1 hosts
2020-03-11 21:18:34,034 - nornir.core.task -    ERROR -      start() - Host 'Switch01': task 'netmiko_send_command' failed with traceback:
Traceback (most recent call last):
  File "C:\Program Files (x86)\Python38-32\lib\site-packages\netmiko\base_connection.py", line 892, in establish_connection
    self.remote_conn_pre.connect(**ssh_connect_params)
  File "C:\Program Files (x86)\Python38-32\lib\site-packages\paramiko\client.py", line 368, in connect
    raise NoValidConnectionsError(errors)
paramiko.ssh_exception.NoValidConnectionsError: [Errno None] Unable to connect to port 22 on 192.168.0.1

During handling of the above exception, another exception occurred:

Traceback (most recent call last):
  File "C:\Program Files (x86)\Python38-32\lib\site-packages\nornir\core\task.py", line 85, in start
    r = self.task(self, **self.params)
  File "C:\Program Files (x86)\Python38-32\lib\site-packages\nornir\plugins\tasks\networking\netmiko_send_command.py", line 26, in netmiko_send_command
    net_connect = task.host.get_connection("netmiko", task.nornir.config)
  File "C:\Program Files (x86)\Python38-32\lib\site-packages\nornir\core\inventory.py", line 294, in get_connection
    self.open_connection(
  File "C:\Program Files (x86)\Python38-32\lib\site-packages\nornir\core\inventory.py", line 345, in open_connection
    self.connections[connection].open(
  File "C:\Program Files (x86)\Python38-32\lib\site-packages\nornir\plugins\connections\netmiko.py", line 58, in open
    self.connection = ConnectHandler(**parameters)
  File "C:\Program Files (x86)\Python38-32\lib\site-packages\netmiko\ssh_dispatcher.py", line 252, in ConnectHandler
    return ConnectionClass(*args, **kwargs)
  File "C:\Program Files (x86)\Python38-32\lib\site-packages\netmiko\base_connection.py", line 318, in __init__
    self._open()
  File "C:\Program Files (x86)\Python38-32\lib\site-packages\netmiko\base_connection.py", line 323, in _open
    self.establish_connection()
  File "C:\Program Files (x86)\Python38-32\lib\site-packages\netmiko\base_connection.py", line 898, in establish_connection
    raise NetmikoTimeoutException(msg)
netmiko.ssh_exception.NetmikoTimeoutException: Connection to device timed-out: cisco_ios 192.168.0.1:22

2020-03-11 21:20:20,347 -  nornir.core -     INFO -        run() - Running task 'nornir_group_of_tasks' with args {'dict_of_devices': {'SERVER1': {'hostname': '192.168.0.15', 'port': 22, 'username': 'root', 'password': 'linux', 'platform': 'linux', 'commands': ['ls -la', 'pwd', 'uname -a']}}} on 1 hosts
2020-03-11 21:20:57,002 -  nornir.core -     INFO -        run() - Running task 'nornir_group_of_tasks' with args {'dict_of_devices': {'SERVER1': {'hostname': '192.168.0.15', 'port': 22, 'username': 'root', 'password': 'linux', 'platform': 'linux', 'commands': ['ls -la', 'pwd', 'uname -a']}}} on 1 hosts
2020-03-11 21:22:20,979 -  nornir.core -     INFO -        run() - Running task 'nornir_group_of_tasks' with args {'dict_of_devices': {'SERVER1': {'hostname': '192.168.0.15', 'port': 22, 'username': 'root', 'password': 'linux', 'platform': 'linux', 'commands': ['echo ABC', 'pwd', 'uname -a']}}} on 1 hosts
2020-03-11 21:23:26,070 -  nornir.core -     INFO -        run() - Running task 'nornir_group_of_tasks' with args {'dict_of_devices': {'SERVER1': {'hostname': '192.168.0.15', 'port': 22, 'username': 'root', 'password': 'linux', 'platform': 'linux', 'commands': ['echo ABC', 'pwd', 'uname -a']}, 'SERVER2': {'hostname': '192.168.0.15', 'port': 22, 'username': 'root', 'password': 'linux', 'platform': 'linux', 'commands': ['echo ABC', 'pwd', 'uname -a']}}} on 2 hosts
2020-03-11 21:23:44,796 -  nornir.core -     INFO -        run() - Running task 'nornir_group_of_tasks' with args {'dict_of_devices': {'SERVER1': {'hostname': '192.168.0.15', 'port': 22, 'username': 'root', 'password': 'linux', 'platform': 'linux', 'commands': ['echo ABC', 'pwd', 'uname -a']}, 'SERVER2': {'hostname': '192.168.0.15', 'port': 22, 'username': 'root', 'password': 'linux', 'platform': 'linux', 'commands': ['echo ABC', 'pwd', 'uname -a']}}} on 2 hosts
